Workbook

Sheet Outputs
A2: No. of prisoners | B2: 1440 | C2: Input figure here
A4: Required GIFA | B4: =SUM(B11:B22) -> 56706
A5: Calculated Total GIFA ÷ Millsike Density
A7: No. of Houseblocks req'd | B7: =ROUNDUP(B2/Calculation!C3,0) -> 6
A8: Calculated Total GIFA ÷ Millsike Density
A10: Buildings | B10: GIFA
A11: ERH (core) | B11: =Calculation!C12 -> 3059
A12: ERH (offices) | B12: =$B$2*Calculation!E13 -> 200
A13: ERH (visits hall) | B13: =$B$2*Calculation!E14 -> 1400
A14: Support | B14: =Calculation!C15 -> 770
A15: Central services (core) | B15: =Calculation!C16 -> 3130
A16: Central services (education) | B16: =$B$2*Calculation!E17 -> 1500
A17: Central services (gym) | B17: =$B$2*Calculation!E18 -> 300
A18: Kitchen | B18: =Calculation!C19 -> 1926
A19: Workshop | B19: =Calculation!C20+((B7-6)*1200) -> 7257
A20: CASU | B20: =Calculation!C21*IF($B$7>=12,2,1) -> 648
A21: Houseblock | B21: =((B7-1)*Calculation!C22) -> 30430
A22: OPU | B22: =Calculation!C23*IF($B$7>=12,2,1) -> 6086
A24: Required Acres | B24: =((B2*Calculation!C5)/4046.86) -> 51.061811
A25: Calculated Total GIFA ÷ Millsike Density
A27: Start on site | B27: Q3 (2026) | C27: Choose start on site period
A29: Programme (wks) | B29: =Calculation!C7+((B7-1)*Calculation!C8)+Calculation!C9 -> 154
A30: Houseblock Duration + ((Number of Blocks - 1) × 4 Weeks) + Commissioning
A32: Description | B32: Cost / m2
A33: Demo | B33: =$B$4*Calculation!C34 -> 0
A34: Substructure | B34: {=($B$4*Calculation!C35)*Calculation!$C$48*INDEX(Calculation!$D$59:$D$84,MATCH($B$27,Calculation!$B$59:$B$84,0)+ROUND($B$29/2/13,0))} -> 30945983
A35: Superstructure Env | B35: {=($B$4*Calculation!C36)*Calculation!$C$48*INDEX(Calculation!$D$59:$D$84,MATCH($B$27,Calculation!$B$59:$B$84,0)+ROUND($B$29/2/13,0))} -> 1.1105117e+08
A36: Superstructure Sub | B36: {=($B$4*Calculation!C37)*Calculation!$C$48*INDEX(Calculation!$D$59:$D$84,MATCH($B$27,Calculation!$B$59:$B$84,0)+ROUND($B$29/2/13,0))} -> 29514290
A37: Finishes | B37: {=($B$4*Calculation!C38)*Calculation!$C$48*INDEX(Calculation!$D$59:$D$84,MATCH($B$27,Calculation!$B$59:$B$84,0)+ROUND($B$29/2/13,0))} -> 25628938
A38: Fittings | B38: {=($B$4*Calculation!C39)*Calculation!$C$48*INDEX(Calculation!$D$59:$D$84,MATCH($B$27,Calculation!$B$59:$B$84,0)+ROUND($B$29/2/13,0))} -> 8450973.6
A39: M&E | B39: {=($B$4*Calculation!C40)*Calculation!$C$48*INDEX(Calculation!$D$59:$D$84,MATCH($B$27,Calculation!$B$59:$B$84,0)+ROUND($B$29/2/13,0))} -> 1.7582529e+08
A40: External works | B40: {=($B$4*Calculation!C41)*Calculation!$C$48*INDEX(Calculation!$D$59:$D$84,MATCH($B$27,Calculation!$B$59:$B$84,0)+ROUND($B$29/2/13,0))} -> 1.3227556e+08
A41: TOTAL | B41: =SUM(B33:B40) -> 5.1369221e+08

Sheet Calculation
B2: Prisoners (Total) | C2: 1440
B3: Prisoners (per HB) | C3: 240
B4: GIFA | C4: =SUM(C12:C21)+(5*C22)+C23 -> 56706
B5: Site area | C5: 143.5
B6: Area / prisoner | C6: =C4/C2 -> 39.379167
B7: Programme (HBs) | C7: 122
B8: Programme (Stagger) | C8: 4
B9: Programme (Commissioning) | C9: 12
B11: Building | C11: GIFA | D11: Status | E11: m2 / person | F11: Notes
B12: ERH (core) | C12: 3059 | D12: Fixed
B13: ERH (offices) | C13: =$C$2*E13 -> 200 | E13: =200/1440 -> 0.13888889
B14: ERH (visits hall) | C14: =$C$2*E14 -> 1400 | E14: =1400/1440 -> 0.97222222
B15: Support | C15: 770 | D15: Fixed
B16: Central services (core) | C16: 3130 | D16: Fixed
B17: Central services (education) | C17: =$C$2*E17 -> 1500 | E17: =1500/1440 -> 1.0416667
B18: Central services (gym) | C18: =$C$2*E18 -> 300 | E18: =300/1440 -> 0.20833333
B19: Kitchen | C19: 1926 | D19: Fixed
B20: Workshop | C20: 7257 | E20: 1200 | F20: per additional HB
B21: CASU | C21: 648 | D21: Fixed | F21: 1 additional CASU per 6 HBs
B22: Houseblock | C22: 6086 | D22: Fixed
B23: OPU | C23: 6086 | D23: Fixed | F23: 1 additional OPU per 6 HBs
B25: Description | C25: Cost / m2 | D25: Notes
B26: Profit | C26: 119.35 | D26: Mark to transition costs to rows 34 to 42
B27: Central OH | C27: 313.72 | D27: Mark to transition costs to rows 34 to 43
B28: Site OH A | C28: 438.59 | D28: Mark to transition costs to rows 34 to 44
B29: Site OH B | C29: 494.42 | D29: Mark to transition costs to rows 34 to 45
B30: Risk | C30: 143.34 | D30: Mark to transition costs to rows 34 to 46
B31: Specialist fees | C31: 31.41 | D31: Mark to transition costs to rows 34 to 47
B32: Precon fees | C32: 21.18 | D32: Mark to transition costs to rows 34 to 48
B33: Regulatory fees | D33: Mark to transition costs to rows 34 to 49
B34: Demo
B35: Substructure | C35: 395.77
B36: Superstructure Env | C36: 1420.24
B37: Superstructure Sub | C37: 377.46
B38: Finishes | C38: 327.77
B39: Fittings | C39: 108.08
B40: M&E | C40: 2248.64
B41: External works | C41: 1691.68
B42: Abnormal, Site Influences & Specific Requirements
B43: Minor works | C43: -118.84
...
